[2023-12-19T05:21:25.625+0000] {taskinstance.py:1159} INFO - Dependencies all met for dep_context=non-requeueable deps ti=<TaskInstance: COVID19_Prediction_Classification-v01.generate_date_parts.generate-date-parts-of-Test_date scheduled__2023-12-01T00:00:00+00:00 [queued]>
[2023-12-19T05:21:25.628+0000] {taskinstance.py:1159} INFO - Dependencies all met for dep_context=requeueable deps ti=<TaskInstance: COVID19_Prediction_Classification-v01.generate_date_parts.generate-date-parts-of-Test_date scheduled__2023-12-01T00:00:00+00:00 [queued]>
[2023-12-19T05:21:25.629+0000] {taskinstance.py:1361} INFO - Starting attempt 3 of 6
[2023-12-19T05:21:25.636+0000] {taskinstance.py:1382} INFO - Executing <Task(PostgresOperator): generate-date-parts-of-Test_date> on 2023-12-01 00:00:00+00:00
[2023-12-19T05:21:25.638+0000] {standard_task_runner.py:57} INFO - Started process 812 to run task
[2023-12-19T05:21:25.640+0000] {standard_task_runner.py:84} INFO - Running: ['***', 'tasks', 'run', 'COVID19_Prediction_Classification-v01.generate_date_parts', 'generate-date-parts-of-Test_date', 'scheduled__2023-12-01T00:00:00+00:00', '--job-id', '9', '--raw', '--subdir', 'DAGS_FOLDER/covid19_project.py', '--cfg-path', '/tmp/tmp2w1axhz8']
[2023-12-19T05:21:25.642+0000] {standard_task_runner.py:85} INFO - Job 9: Subtask generate-date-parts-of-Test_date
[2023-12-19T05:21:25.670+0000] {task_command.py:416} INFO - Running <TaskInstance: COVID19_Prediction_Classification-v01.generate_date_parts.generate-date-parts-of-Test_date scheduled__2023-12-01T00:00:00+00:00 [running]> on host 44c88b785d30
[2023-12-19T05:21:25.694+0000] {abstractoperator.py:709} ERROR - Exception rendering Jinja template for task 'generate-date-parts-of-Test_date', field 'sql'. Template: '-- params: table_name, col_name, month_col_name, year_col_name, dom_col_name\n\n-- Add columns\nALTER TABLE {{ params.table_name }}\nADD COLUMN IF NOT EXISTS {{ params.month_col_name }} INTEGER, \nADD COLUMN IF NOT EXISTS {{ params.year_col_name }} INTEGER, \nADD COLUMN IF NOT EXISTS {{ params.dom_col_name }} INTEGER;\n\n-- fill columns with their proper values\nUPDATE {{ params.table_name }}\nSET \n    {{ params.month_col_name }} = EXTRACT(MONTH FROM {{ params.col_name }}),\n    {{ params.year_col_name }} = EXTRACT(YEAR FROM {{ params.col_name }}),\n    {{ params.dom_col_name }} = EXTRACT(DAY FROM {{ params.col_name }});'
Traceback (most recent call last):
  File "/home/airflow/.local/lib/python3.8/site-packages/airflow/models/abstractoperator.py", line 701, in _do_render_template_fields
    rendered_content = self.render_template(
  File "/home/airflow/.local/lib/python3.8/site-packages/airflow/template/templater.py", line 155, in render_template
    return self._render(template, context)
  File "/home/airflow/.local/lib/python3.8/site-packages/airflow/models/abstractoperator.py", line 655, in _render
    return super()._render(template, context, dag=dag)
  File "/home/airflow/.local/lib/python3.8/site-packages/airflow/template/templater.py", line 112, in _render
    return render_template_to_string(template, context)
  File "/home/airflow/.local/lib/python3.8/site-packages/airflow/utils/helpers.py", line 289, in render_template_to_string
    return render_template(template, cast(MutableMapping[str, Any], context), native=False)
  File "/home/airflow/.local/lib/python3.8/site-packages/airflow/utils/helpers.py", line 284, in render_template
    return "".join(nodes)
  File "<template>", line 13, in root
  File "/home/airflow/.local/lib/python3.8/site-packages/jinja2/runtime.py", line 852, in _fail_with_undefined_error
    raise self._undefined_exception(self._undefined_message)
jinja2.exceptions.UndefinedError: 'dict object' has no attribute 'table_name'
[2023-12-19T05:21:25.695+0000] {taskinstance.py:1937} ERROR - Task failed with exception
Traceback (most recent call last):
  File "/home/airflow/.local/lib/python3.8/site-packages/airflow/models/taskinstance.py", line 1518, in _run_raw_task
    self._execute_task_with_callbacks(context, test_mode, session=session)
  File "/home/airflow/.local/lib/python3.8/site-packages/airflow/models/taskinstance.py", line 1647, in _execute_task_with_callbacks
    task_orig = self.render_templates(context=context)
  File "/home/airflow/.local/lib/python3.8/site-packages/airflow/models/taskinstance.py", line 2285, in render_templates
    original_task.render_template_fields(context)
  File "/home/airflow/.local/lib/python3.8/site-packages/airflow/models/baseoperator.py", line 1243, in render_template_fields
    self._do_render_template_fields(self, self.template_fields, context, jinja_env, set())
  File "/home/airflow/.local/lib/python3.8/site-packages/airflow/utils/session.py", line 79, in wrapper
    return func(*args, session=session, **kwargs)
  File "/home/airflow/.local/lib/python3.8/site-packages/airflow/models/abstractoperator.py", line 701, in _do_render_template_fields
    rendered_content = self.render_template(
  File "/home/airflow/.local/lib/python3.8/site-packages/airflow/template/templater.py", line 155, in render_template
    return self._render(template, context)
  File "/home/airflow/.local/lib/python3.8/site-packages/airflow/models/abstractoperator.py", line 655, in _render
    return super()._render(template, context, dag=dag)
  File "/home/airflow/.local/lib/python3.8/site-packages/airflow/template/templater.py", line 112, in _render
    return render_template_to_string(template, context)
  File "/home/airflow/.local/lib/python3.8/site-packages/airflow/utils/helpers.py", line 289, in render_template_to_string
    return render_template(template, cast(MutableMapping[str, Any], context), native=False)
  File "/home/airflow/.local/lib/python3.8/site-packages/airflow/utils/helpers.py", line 284, in render_template
    return "".join(nodes)
  File "<template>", line 13, in root
  File "/home/airflow/.local/lib/python3.8/site-packages/jinja2/runtime.py", line 852, in _fail_with_undefined_error
    raise self._undefined_exception(self._undefined_message)
jinja2.exceptions.UndefinedError: 'dict object' has no attribute 'table_name'
[2023-12-19T05:21:25.702+0000] {taskinstance.py:1400} INFO - Marking task as UP_FOR_RETRY. dag_id=COVID19_Prediction_Classification-v01.generate_date_parts, task_id=generate-date-parts-of-Test_date, execution_date=20231201T000000, start_date=20231219T052125, end_date=20231219T052125
[2023-12-19T05:21:25.707+0000] {standard_task_runner.py:104} ERROR - Failed to execute job 9 for task generate-date-parts-of-Test_date ('dict object' has no attribute 'table_name'; 812)
[2023-12-19T05:21:25.734+0000] {local_task_job_runner.py:228} INFO - Task exited with return code 1
[2023-12-19T05:21:25.751+0000] {taskinstance.py:2778} INFO - 0 downstream tasks scheduled from follow-on schedule check
